[2025-08-14T13:13:17.850+0000] {taskinstance.py:1956} INFO - Dependencies all met for dep_context=non-requeueable deps ti=<TaskInstance: bayir_express_etl.etl_users manual__2025-08-14T13:12:33.887787+00:00 [queued]>
[2025-08-14T13:13:17.866+0000] {taskinstance.py:1956} INFO - Dependencies all met for dep_context=requeueable deps ti=<TaskInstance: bayir_express_etl.etl_users manual__2025-08-14T13:12:33.887787+00:00 [queued]>
[2025-08-14T13:13:17.868+0000] {taskinstance.py:2170} INFO - Starting attempt 1 of 2
[2025-08-14T13:13:17.896+0000] {taskinstance.py:2191} INFO - Executing <Task(PythonOperator): etl_users> on 2025-08-14 13:12:33.887787+00:00
[2025-08-14T13:13:17.904+0000] {standard_task_runner.py:60} INFO - Started process 97 to run task
[2025-08-14T13:13:17.912+0000] {standard_task_runner.py:87} INFO - Running: ['airflow', 'tasks', 'run', 'bayir_express_etl', 'etl_users', 'manual__2025-08-14T13:12:33.887787+00:00', '--job-id', '3', '--raw', '--subdir', 'DAGS_FOLDER/bayir_express_etl.py', '--cfg-path', '/tmp/tmpm06sp9ts']
[2025-08-14T13:13:17.917+0000] {standard_task_runner.py:88} INFO - Job 3: Subtask etl_users
[2025-08-14T13:13:18.013+0000] {task_command.py:423} INFO - Running <TaskInstance: bayir_express_etl.etl_users manual__2025-08-14T13:12:33.887787+00:00 [running]> on host 434307a3e534
[2025-08-14T13:13:18.134+0000] {taskinstance.py:2480} INFO - Exporting env vars: AIRFLOW_CTX_DAG_OWNER='airflow' AIRFLOW_CTX_DAG_ID='bayir_express_etl' AIRFLOW_CTX_TASK_ID='etl_users' AIRFLOW_CTX_EXECUTION_DATE='2025-08-14T13:12:33.887787+00:00' AIRFLOW_CTX_TRY_NUMBER='1' AIRFLOW_CTX_DAG_RUN_ID='manual__2025-08-14T13:12:33.887787+00:00'
[2025-08-14T13:13:48.416+0000] {taskinstance.py:2698} ERROR - Task failed with exception
Traceback (most recent call last):
  File "/home/airflow/.local/lib/python3.8/site-packages/airflow/models/taskinstance.py", line 433, in _execute_task
    result = execute_callable(context=context, **execute_callable_kwargs)
  File "/home/airflow/.local/lib/python3.8/site-packages/airflow/operators/python.py", line 199, in execute
    return_value = self.execute_callable()
  File "/home/airflow/.local/lib/python3.8/site-packages/airflow/operators/python.py", line 216, in execute_callable
    return self.python_callable(*self.op_args, **self.op_kwargs)
  File "/opt/airflow/dags/bayir_express_etl.py", line 28, in etl_users
    df = extract_collection("users")
  File "/opt/airflow/project/etl/extract.py", line 10, in extract_collection
    data = list(collection.find())
  File "/home/airflow/.local/lib/python3.8/site-packages/pymongo/synchronous/cursor.py", line 1281, in __next__
    return self.next()
  File "/home/airflow/.local/lib/python3.8/site-packages/pymongo/synchronous/cursor.py", line 1257, in next
    if len(self._data) or self._refresh():
  File "/home/airflow/.local/lib/python3.8/site-packages/pymongo/synchronous/cursor.py", line 1205, in _refresh
    self._send_message(q)
  File "/home/airflow/.local/lib/python3.8/site-packages/pymongo/synchronous/cursor.py", line 1100, in _send_message
    response = client._run_operation(
  File "/home/airflow/.local/lib/python3.8/site-packages/pymongo/_csot.py", line 119, in csot_wrapper
    return func(self, *args, **kwargs)
  File "/home/airflow/.local/lib/python3.8/site-packages/pymongo/synchronous/mongo_client.py", line 1754, in _run_operation
    return self._retryable_read(
  File "/home/airflow/.local/lib/python3.8/site-packages/pymongo/synchronous/mongo_client.py", line 1863, in _retryable_read
    return self._retry_internal(
  File "/home/airflow/.local/lib/python3.8/site-packages/pymongo/_csot.py", line 119, in csot_wrapper
    return func(self, *args, **kwargs)
  File "/home/airflow/.local/lib/python3.8/site-packages/pymongo/synchronous/mongo_client.py", line 1819, in _retry_internal
    return _ClientConnectionRetryable(
  File "/home/airflow/.local/lib/python3.8/site-packages/pymongo/synchronous/mongo_client.py", line 2554, in run
    return self._read() if self._is_read else self._write()
  File "/home/airflow/.local/lib/python3.8/site-packages/pymongo/synchronous/mongo_client.py", line 2689, in _read
    self._server = self._get_server()
  File "/home/airflow/.local/lib/python3.8/site-packages/pymongo/synchronous/mongo_client.py", line 2645, in _get_server
    return self._client._select_server(
  File "/home/airflow/.local/lib/python3.8/site-packages/pymongo/synchronous/mongo_client.py", line 1649, in _select_server
    server = topology.select_server(
  File "/home/airflow/.local/lib/python3.8/site-packages/pymongo/synchronous/topology.py", line 398, in select_server
    server = self._select_server(
  File "/home/airflow/.local/lib/python3.8/site-packages/pymongo/synchronous/topology.py", line 376, in _select_server
    servers = self.select_servers(
  File "/home/airflow/.local/lib/python3.8/site-packages/pymongo/synchronous/topology.py", line 283, in select_servers
    server_descriptions = self._select_servers_loop(
  File "/home/airflow/.local/lib/python3.8/site-packages/pymongo/synchronous/topology.py", line 333, in _select_servers_loop
    raise ServerSelectionTimeoutError(
pymongo.errors.ServerSelectionTimeoutError: No replica set members found yet, Timeout: 30s, Topology Description: <TopologyDescription id: 689de0eebe695a6625562b63, topology_type: ReplicaSetNoPrimary, servers: [<ServerDescription ('ac-x8xlpir-shard-00-00.ntnjvtx.mongodb.net', 27017) server_type: Unknown, rtt: None>, <ServerDescription ('ac-x8xlpir-shard-00-01.ntnjvtx.mongodb.net', 27017) server_type: Unknown, rtt: None>, <ServerDescription ('ac-x8xlpir-shard-00-02.ntnjvtx.mongodb.net', 27017) server_type: Unknown, rtt: None>]>
[2025-08-14T13:13:48.433+0000] {taskinstance.py:1138} INFO - Marking task as UP_FOR_RETRY. dag_id=bayir_express_etl, task_id=etl_users, execution_date=20250814T131233, start_date=20250814T131317, end_date=20250814T131348
[2025-08-14T13:13:48.458+0000] {standard_task_runner.py:107} ERROR - Failed to execute job 3 for task etl_users (No replica set members found yet, Timeout: 30s, Topology Description: <TopologyDescription id: 689de0eebe695a6625562b63, topology_type: ReplicaSetNoPrimary, servers: [<ServerDescription ('ac-x8xlpir-shard-00-00.ntnjvtx.mongodb.net', 27017) server_type: Unknown, rtt: None>, <ServerDescription ('ac-x8xlpir-shard-00-01.ntnjvtx.mongodb.net', 27017) server_type: Unknown, rtt: None>, <ServerDescription ('ac-x8xlpir-shard-00-02.ntnjvtx.mongodb.net', 27017) server_type: Unknown, rtt: None>]>; 97)
[2025-08-14T13:13:48.509+0000] {local_task_job_runner.py:234} INFO - Task exited with return code 1
[2025-08-14T13:13:48.535+0000] {taskinstance.py:3280} INFO - 0 downstream tasks scheduled from follow-on schedule check
